#VRML_SIM R2022a utf8
WorldInfo {
}
Viewpoint {
  orientation 0.15861765100613312 0.006210120539714701 -0.9873205534132159 3.243416780225331
  position 4.822038178328731 -0.7146890622239216 4.531347139049453
}
TexturedBackground {
  texture "mars"
}
TexturedBackgroundLight {
  luminosity 2
}
UnevenTerrain {
  appearance SandyGround {
    colorOverride 0.5 0.5 0.4
    textureTransform TextureTransform {
      scale 50 50
    }
  }
}
Robot {
  translation -0.4944348215944826 0.14069217502662024 3.245345408430391
  rotation -0.9668030878235777 -0.1425439218238576 -0.21206843170512027 0.2422129628018895
  children [
    DEF body Shape {
      appearance HammeredCopper {
      }
      geometry Box {
        size 0.7 0.5 0.2
      }
    }
    Solid {
      translation 0 0 0.19
      children [
        Solid {
          translation 0.3 -0.19 -0.05
          children [
            Shape {
              appearance Copper {
              }
              geometry Cylinder {
                height 0.1
                radius 0.02
              }
            }
          ]
          name "solar_panel_support1"
        }
        Solid {
          translation 0.3 0.19 -0.05
          children [
            Shape {
              appearance Copper {
              }
              geometry Cylinder {
                height 0.1
                radius 0.02
              }
            }
          ]
          name "solar_panel_support2"
        }
        Solid {
          translation -0.3 0.19 -0.05
          children [
            Shape {
              appearance Copper {
              }
              geometry Cylinder {
                height 0.1
                radius 0.02
              }
            }
          ]
          name "solar_panel_support3"
        }
        Solid {
          translation -0.3 -0.19 -0.05
          children [
            Shape {
              appearance Copper {
              }
              geometry Cylinder {
                height 0.1
                radius 0.02
              }
            }
          ]
          name "solar_panel_support4"
        }
      ]
      name "solar_panel"
    }
    Solid {
      translation -0.18 -0.24 0
      children [
        SliderJoint {
          jointParameters JointParameters {
            position -7.740339643934236e-06
            minStop -0.1
            staticFriction 1
          }
          device [
            LinearMotor {
              name "linear1_left"
              maxForce 50
            }
          ]
          endPoint Solid {
            translation -0.00017985453301283538 -0.017342787906382884 0.060043545130968635
            rotation -0.9999999928695749 8.057119204137451e-05 -8.814268504930294e-05 1.5708453179831379
            children [
              DEF cylinder1 Shape {
                appearance DamascusSteel {
                }
                geometry Cylinder {
                  height 0.09
                  radius 0.02
                }
              }
              Solid {
                translation 0 0 -0.05
                children [
                  DEF sphere1 Shape {
                    appearance BrushedSteel {
                    }
                    geometry Sphere {
                      radius 0.02
                    }
                  }
                  Solid {
                    translation 0 0.1 1.79608e-07
                    rotation -1 0 0 -1.5707953071795862
                    children [
                      DEF cylinder2 Shape {
                        appearance BrushedSteel {
                        }
                        geometry Cylinder {
                          height 0.2
                          radius 0.02
                        }
                      }
                      Solid {
                        translation 0 0 -0.11
                        children [
                          DEF sphere1 Shape {
                            appearance BrushedSteel {
                            }
                            geometry Sphere {
                              radius 0.02
                            }
                          }
                          Solid {
                            translation 0 -0.03 -9.99999e-08
                            rotation 1 0 0 1.5708
                            children [
                              DEF cylinder3 Shape {
                                appearance BrushedSteel {
                                }
                                geometry Cylinder {
                                  height 0.06
                                  radius 0.02
                                }
                              }
                              HingeJoint {
                                jointParameters HingeJointParameters {
                                  position -4.627712372825804
                                  axis 0 0 1
                                  anchor -9.51224e-05 0.00113507 0.0800056
                                }
                                device [
                                  RotationalMotor {
                                    name "wheel1_left"
                                  }
                                ]
                                endPoint Solid {
                                  translation 0.001001548622514501 0.0015508736330995187 0.0800641
                                  rotation -4.819684027318445e-07 8.302117474941898e-07 0.9999999999995393 1.6554768380434253
                                  children [
                                    DEF wheel Shape {
                                      appearance DamascusSteel {
                                      }
                                      geometry Cylinder {
                                        height 0.15
                                        radius 0.15
                                      }
                                    }
                                  ]
                                  boundingObject USE wheel
                                  physics Physics {
                                    mass 1
                                  }
                                  linearVelocity -1.5616010222998633e-05 -1.9358180202748028e-05 4.438321555602953e-06
                                  angularVelocity -1.4299836407304954e-05 -2.6186910152936466e-05 2.137126914113904e-06
                                }
                              }
                            ]
                            boundingObject USE cylinder3
                            physics DEF phy1 Physics {
                              mass 1
                            }
                          }
                        ]
                        name "solid(1)"
                        boundingObject USE sphere1
                        physics USE phy1
                      }
                    ]
                    boundingObject USE cylinder2
                    physics USE phy1
                  }
                ]
                boundingObject USE sphere1
                physics USE phy1
              }
            ]
            boundingObject USE cylinder1
            physics USE phy1
            linearVelocity -1.2755530237863927e-05 -1.6513307254932254e-05 2.9295584671657276e-06
            angularVelocity -1.2064293587806191e-05 7.1675986863966015e-06 -5.896378584936401e-06
          }
        }
      ]
      name "wheel1_left_system"
      physics USE phy1
    }
  ]
  boundingObject USE body
  physics DEF phy Physics {
    mass 1
  }
  controller "sd"
  linearVelocity -1.0167354856755006e-05 -1.514275134549631e-05 -6.012166989549824e-08
  angularVelocity -1.1627277041075362e-05 6.813514300281461e-06 -5.6977596785151955e-06
}
